Workbook

Sheet Dépenses
A1: Fournisseur | B1: Facture | C1: Date | D1: Montant | J1: Fournisseur
A2: SMPA | B2: F0590 | C2: 45022 | D2: 500.5 | J2: SMPA
A3: SMPA | B3: F0824 | C3: 45087 | D3: 812.4 | J3: SNAPRINT
A4: SMPA | B4: F0951 | C4: 45119 | D4: 799.385 | J4: Maison D'Art
A5: SMPA | B5: F1100 | C5: 45141 | D5: 666.112 | J5: Kamel hidri
A6: SMPA | B6: F1248 | C6: 45193 | D6: 616 | J6: TOUT BUREAU
A7: SMPA | B7: F1320 | C7: 45210 | D7: 663.444 | J7: NATBAG
A8: SNAPRINT | B8: 2023-0195 | C8: 45251 | D8: 1081.75 | J8: ORIENTAL DESIGN
A9: SMPA | B9: F1496 | C9: 45251 | D9: 462.216 | J9: Fehri Bel hadj
A10: Maison D'Art | B10: 292 | C10: 45266 | D10: 934.58 | J10: KACO SA
A11: Kamel hidri | B11: - | C11: 45266 | D11: 420.551 | J11: ASCOM
A12: TOUT BUREAU | B12: F2313884 | C12: 45275 | D12: 762 | J12: My Print Tunisia
A13: NATBAG | B13: 000059 | C13: 45278 | D13: 1690.2 | J13: Helmi Abbassi
A14: ORIENTAL DESIGN | B14: 20230162V | C14: 45281 | D14: 1900 | J14: Ben Ghorbal Kawther
A15: Fehri Bel hadj | B15: 022/2023 | C15: 45281 | D15: 1425 | J15: Cabinet Fethi Hamrouni
A16: SNAPRINT | B16: 2023-01955 | C16: 45281 | D16: 3640 | J16: Orange Tunisie
A17: KACO SA | B17: 202308 | C17: 45285 | D17: 1800 | J17: Foire International Sousse
A18: SMPA | B18: F1558 | C18: 45288 | D18: 504.462 | J18: ALCHIMY
A19: ASCOM | B19: FC256 | C19: 45315 | D19: 950 | J19: BIO SPACE
A20: Kamel hidri | B20: - | C20: 45307 | D20: 3932.2499 | J20: 3P
A21: Maison D'Art | B21: 301 | C21: 45307 | D21: 8411.2149 | J21: SBCD
A22: My Print Tunisia | B22: 24044 | C22: 45484 | D22: 1797 | J22: LEM
A23: Helmi Abbassi | B23: 393 | C23: 45490 | D23: 375.2 | J23: KOBOX
A24: Ben Ghorbal Kawther | B24: 3732 | C24: 45488 | D24: 210.25 | J24: Karim Balah
A25: Cabinet Fethi Hamrouni | B25: ac073/24 | C25: 45493 | D25: 1500.476 | J25: Yosra Sayah
A26: Orange Tunisie | B26: 2401316943 | C26: 45292 | D26: 64.286 | J26: Recharge carte tech
A27: Orange Tunisie | B27: 2401316943 | C27: 45323 | D27: 64.286 | J27: Majdi PHOTOGRAPHE
A28: Orange Tunisie | B28: 2401316943 | C28: 45352 | D28: 64.286 | J28: Sofien Cherif
A29: Orange Tunisie | B29: 2401316943 | C29: 45383 | D29: 64.286 | J29: CNSS
A30: Orange Tunisie | B30: 2401316943 | C30: 45413 | D30: 64.286 | J30: Pénalité
A31: Orange Tunisie | B31: 2401316943 | C31: 45444 | D31: 64.286 | J31: Lazhar Riahi
A32: Orange Tunisie | B32: 2401316943 | C32: 45474 | D32: 64.286 | J32: Riadh Laouiti
A33: Orange Tunisie | B33: 2401316943 | C33: 45505 | D33: 64.286 | J33: Zitoun Artisanat
A34: Foire International Sousse | B34: FA2400470 | C34: 45501 | D34: 365 | J34: EL FEKI BILEL
A35: ALCHIMY | B35: FAC023 | C35: 45462 | D35: 1116.9 | J35: Chedly Gara
A36: BIO SPACE | C36: 45439 | D36: 600 | J36: Outils emballage
A37: Fehri Bel hadj | C37: 45352 | D37: 21028.03 | J37: Open Space Lab
A38: Orange Tunisie | B38: 2401316943 | C38: 45536 | D38: 64.286 | J38: Gaya
A39: Orange Tunisie | B39: 2401316943 | C39: 45566 | D39: 64.286 | J39: Jeux bittounsi
A40: 3P | B40: FAC241984 | C40: 45617 | D40: 625 | J40: Zoub ceramic
...

Sheet Revenus par client
A1: Client | B1: Total en DT | C1: Nombre de marchés | D1: % CA
A2: SMPA | B2: =SUMIF(Dépenses!A:A,'Revenus par client'!A2,Dépenses!D:D) -> 5024.519 | C2: =COUNTIF(Dépenses!A:A,'Revenus par client'!A2) -> 8 | D2: =B2/$B$86 -> 0.026887915
A3: SNAPRINT | B3: =SUMIF(Dépenses!A:A,'Revenus par client'!A3,Dépenses!D:D) -> 4721.75 | C3: =COUNTIF(Dépenses!A:A,'Revenus par client'!A3) -> 2 | D3: =B3/$B$86 -> 0.025267694
A4: Maison D'Art | B4: =SUMIF(Dépenses!A:A,'Revenus par client'!A4,Dépenses!D:D) -> 9345.7949 | C4: =COUNTIF(Dépenses!A:A,'Revenus par client'!A4) -> 2 | D4: =B4/$B$86 -> 0.050012536
A5: Kamel HYDRY | B5: =SUMIF(Dépenses!A:A,'Revenus par client'!A5,Dépenses!D:D) -> 0 | C5: =COUNTIF(Dépenses!A:A,'Revenus par client'!A5) -> 0 | D5: =B5/$B$86 -> 0
A6: TOUT BUREAU | B6: =SUMIF(Dépenses!A:A,'Revenus par client'!A6,Dépenses!D:D) -> 762 | C6: =COUNTIF(Dépenses!A:A,'Revenus par client'!A6) -> 1 | D6: =B6/$B$86 -> 0.0040777219
A7: NATBAG | B7: =SUMIF(Dépenses!A:A,'Revenus par client'!A7,Dépenses!D:D) -> 4316.2 | C7: =COUNTIF(Dépenses!A:A,'Revenus par client'!A7) -> 2 | D7: =B7/$B$86 -> 0.023097458
A8: ORIENTAL DESIGN | B8: =SUMIF(Dépenses!A:A,'Revenus par client'!A8,Dépenses!D:D) -> 40138 | C8: =COUNTIF(Dépenses!A:A,'Revenus par client'!A8) -> 13 | D8: =B8/$B$86 -> 0.21479213
A9: Fehri Bel hadj | B9: =SUMIF(Dépenses!A:A,'Revenus par client'!A9,Dépenses!D:D) -> 22453.03 | C9: =COUNTIF(Dépenses!A:A,'Revenus par client'!A9) -> 2 | D9: =B9/$B$86 -> 0.12015382
A10: KACO SA | B10: =SUMIF(Dépenses!A:A,'Revenus par client'!A10,Dépenses!D:D) -> 2130 | C10: =COUNTIF(Dépenses!A:A,'Revenus par client'!A10) -> 2 | D10: =B10/$B$86 -> 0.011398356
A11: ASCOM | B11: =SUMIF(Dépenses!A:A,'Revenus par client'!A11,Dépenses!D:D) -> 950 | C11: =COUNTIF(Dépenses!A:A,'Revenus par client'!A11) -> 1 | D11: =B11/$B$86 -> 0.005083774
A12: My Print Tunisia | B12: =SUMIF(Dépenses!A:A,'Revenus par client'!A12,Dépenses!D:D) -> 1797 | C12: =COUNTIF(Dépenses!A:A,'Revenus par client'!A12) -> 1 | D12: =B12/$B$86 -> 0.0096163598
A13: Helmi Abbassi | B13: =SUMIF(Dépenses!A:A,'Revenus par client'!A13,Dépenses!D:D) -> 465.2 | C13: =COUNTIF(Dépenses!A:A,'Revenus par client'!A13) -> 2 | D13: =B13/$B$86 -> 0.0024894438
... A82: Soumaya Sellaouti | B82: =SUMIF(Dépenses!A:A,'Revenus par client'!A82,Dépenses!D:D) -> 2048 | C82: =COUNTIF(Dépenses!A:A,'Revenus par client'!A82) -> 2 | D82: =B82/$B$86 -> 0.010959546
A86: Total | B86: =SUM(B2:B82) -> 186869.05

Sheet Bilan
A3: Étiquettes de lignes | B3: Somme de Total en DT | C3: Somme de Nombre de marchés | D3: Somme de % CA
A4: 2.11 STONEWARE | B4: 1948 | C4: 1 | D4: 0.0088409465
A5: 3P | B5: 1761.6 | C5: 3 | D5: 0.007994975
A6: 3P PRINT-PRODUCTION-FIXELS | B6: 150 | C6: 2 | D6: 0.00068077104
A7: ALCHIMY | B7: 1212.9 | C7: 2 | D7: 0.0055047146
A8: Aramex | B8: 334 | C8: 12 | D8: 0.0015158502
A9: ASCOM | B9: 950 | C9: 1 | D9: 0.0043115499
A10: Bannour Ahmed | B10: 650 | C10: 2 | D10: 0.0029500078
A11: Batinconfort Mestiri | B11: 29.649 | C11: 1 | D11: 0.0001345612
A12: Ben Ghorbal Kawther | B12: 294.35 | C12: 2 | D12: 0.0013358997
A13: BIO SPACE | B13: 600 | C13: 1 | D13: 0.0027230841
A14: Brothers Phone Store | B14: 2350 | C14: 1 | D14: 0.010665413
A15: Cabinet Fethi Hamrouni | B15: 1500.476 | C15: 1 | D15: 0.0068098707
... A86: Total général | B86: 220338.4 | C86: 185 | D86: 1

Sheet Feuille4
A1: Client | B1: Total en DT | C1: Nombre de marchés | D1: % CA
A2: 3P | B2: 1761.6 | C2: 3 | D2: 0.007994975

Sheet Feuille5
A1: Client | B1: Total en DT | C1: Nombre de marchés | D1: % CA
A2: Cabinet Fethi Hamrouni | B2: 1500.476 | C2: 1 | D2: 0.0068098707

Sheet Feuille6
A1: Client | B1: Total en DT | C1: Nombre de marchés | D1: % CA
A2: 3P PRINT-PRODUCTION-FIXELS | B2: 150 | C2: 2 | D2: 0.00068077104

Sheet Feuille7
A1: Client | B1: Total en DT | C1: Nombre de marchés | D1: % CA
A2: ALCHIMY | B2: 1212.9 | C2: 2 | D2: 0.0055047146
