Workbook

Sheet Revenus B2B
A1: Client | B1: Facture | C1: Date | D1: MontantHT
A2: WIFAK INTERNATIONAL BANK | B2: 11775 | C2: 45149 | D2: 6050.42
A3: WIFAK INTERNATIONAL BANK | B3: 2024-005 | C3: 45316 | D3: 1700
A4: WIFAK INTERNATIONAL BANK | B4: FAC24-012 | C4: 45427 | D4: 845
A5: WIFAK INTERNATIONAL BANK | B5: FAC24-015 | C5: 45455 | D5: 4150
A6: WIFAK INTERNATIONAL BANK | B6: FAC24-024 | C6: 45636 | D6: 26784
A7: Stram | B7: 2023-051 | C7: 45279 | D7: 5100
A8: Attijari Bank | B8: FAC24-02 | C8: 45359 | D8: =36036+15444 -> 51480
A9: Attijari Leasing | B9: FAC24-010 | C9: 45358 | D9: 1830.4
A10: BH BANK | B10: 2023-053 | C10: 45282 | D10: 7470
A11: SAMFI | B11: 2023-062 | C11: 45288 | D11: 800
A12: SAMFI | B12: 2024-003 | C12: 45322 | D12: 751
A13: SAMFI | B13: FAC24-013 | C13: 45805 | D13: 727
A14: SAMFI | B14: FAC24-016 | C14: 45474 | D14: 544
A15: SAMFI | B15: FAC24-017 | C15: 45503 | D15: 744
A16: SAMFI | B16: FAC24-018 | C16: 45541 | D16: 544
A17: SOFIA TECH | B17: 2023-057 | C17: 45286 | D17: 5460
A18: Tunis Call Center | B18: FAC24-022 | C18: 45609 | D18: 19500
A19: Attijari Bank | B19: Fac25-07 | C19: 45698 | D19: 17407.5
A20: Attijari Bank | B20: Fac25-10 | C20: 45721 | D20: 11605
... A22: Attijari Leasing | B22: Fac25-11 | C22: 45722 | D22: 2194.5
A23: Bank ABC Tunis | B23: FAC25-32 | C23: 45987 | D23: =7475/2 -> 3737.5
A24: Bank ABC Tunis | B24: FAC25-36 | C24: 46006 | D24: 300
A25: Bank ABC Tunis | B25: FAC25-37 | C25: 46006 | D25: =7475/2 -> 3737.5
A26: Digital Services Value | B26: FAC25-13BIS | C26: 45758 | D26: 224.34
A27: Everience | B27: FAC25-02 | C27: 45660 | D27: 50000
A28: Lilas | B28: FAC25-29 | C28: 45979 | D28: 1785
A29: N N FOOD | B29: FAC25-38 | C29: 46007 | D29: 1720
A30: SAMFI | C30: 45659 | D30: 352
A31: SAMFI | C31: 45691 | D31: 416
A32: SAMFI | C32: 45718 | D32: 527
A33: SAMFI | C33: 45750 | D33: 352
A34: SAMFI | C34: 45777 | D34: 576
A35: SAMFI | C35: 45806 | D35: 276
A36: SAMFI | C36: 45839 | D36: 384
A37: SAMFI | C37: 45888 | D37: 320
A38: SAMFI | C38: 45911 | D38: 484
A39: SAMFI | C39: 45944 | D39: 224
A40: SAMFI | C40: 45982 | D40: 352
A41: SBCD | B41: FAC25-34 | C41: 46003 | D41: 605
...

Sheet Revenus par client
A1: Client | B1: Total en DT | C1: Nombre de marchés | D1: % CA
A2: WIFAK INTERNATIONAL BANK | B2: =SUMIF('Revenus B2B'!A:A,'Revenus par client'!A2,'Revenus B2B'!D:D) -> 40115.42 | C2: =COUNTIF('Revenus B2B'!A:A,'Revenus par client'!A2) -> 8 | D2: =B2/$B$21 -> 0.14223175
A3: Stram | B3: =SUMIF('Revenus B2B'!A:A,'Revenus par client'!A3,'Revenus B2B'!D:D) -> 5100 | C3: =COUNTIF('Revenus B2B'!A:A,'Revenus par client'!A3) -> 1 | D3: =B3/$B$21 -> 0.018082371
A4: Attijari Bank | B4: =SUMIF('Revenus B2B'!A:A,'Revenus par client'!A4,'Revenus B2B'!D:D) -> 109504.5 | C4: =COUNTIF('Revenus B2B'!A:A,'Revenus par client'!A4) -> 4 | D4: =B4/$B$21 -> 0.3882551
A5: Attijari Leasing | B5: =SUMIF('Revenus B2B'!A:A,'Revenus par client'!A5,'Revenus B2B'!D:D) -> 4024.9 | C5: =COUNTIF('Revenus B2B'!A:A,'Revenus par client'!A5) -> 2 | D5: =B5/$B$21 -> 0.014270536
A6: BH BANK | B6: =SUMIF('Revenus B2B'!A:A,'Revenus par client'!A6,'Revenus B2B'!D:D) -> 7470 | C6: =COUNTIF('Revenus B2B'!A:A,'Revenus par client'!A6) -> 1 | D6: =B6/$B$21 -> 0.026485355
A7: SAMFI | B7: =SUMIF('Revenus B2B'!A:A,'Revenus par client'!A7,'Revenus B2B'!D:D) -> 9100 | C7: =COUNTIF('Revenus B2B'!A:A,'Revenus par client'!A7) -> 18 | D7: =B7/$B$21 -> 0.032264623
A8: SOFIA TECH | B8: =SUMIF('Revenus B2B'!A:A,'Revenus par client'!A8,'Revenus B2B'!D:D) -> 5460 | C8: =COUNTIF('Revenus B2B'!A:A,'Revenus par client'!A8) -> 1 | D8: =B8/$B$21 -> 0.019358774
A9: Tunis Call Center | B9: =SUMIF('Revenus B2B'!A:A,'Revenus par client'!A9,'Revenus B2B'!D:D) -> 36667.5 | C9: =COUNTIF('Revenus B2B'!A:A,'Revenus par client'!A9) -> 2 | D9: =B9/$B$21 -> 0.13000693
A10: Bank ABC Tunis | B10: =SUMIF('Revenus B2B'!A:A,'Revenus par client'!A10,'Revenus B2B'!D:D) -> 7775 | C10: =COUNTIF('Revenus B2B'!A:A,'Revenus par client'!A10) -> 3 | D10: =B10/$B$21 -> 0.027566752
A11: Digital Services Value | B11: =SUMIF('Revenus B2B'!A:A,'Revenus par client'!A11,'Revenus B2B'!D:D) -> 224.34 | C11: =COUNTIF('Revenus B2B'!A:A,'Revenus par client'!A11) -> 1 | D11: =B11/$B$21 -> 0.00079541159
A12: Everience | B12: =SUMIF('Revenus B2B'!A:A,'Revenus par client'!A12,'Revenus B2B'!D:D) -> 50000 | C12: =COUNTIF('Revenus B2B'!A:A,'Revenus par client'!A12) -> 1 | D12: =B12/$B$21 -> 0.17727815
A13: Lilas | B13: =SUMIF('Revenus B2B'!A:A,'Revenus par client'!A13,'Revenus B2B'!D:D) -> 1785 | C13: =COUNTIF('Revenus B2B'!A:A,'Revenus par client'!A13) -> 1 | D13: =B13/$B$21 -> 0.0063288298
... A18: Transider | B18: =SUMIF('Revenus B2B'!A:A,'Revenus par client'!A18,'Revenus B2B'!D:D) -> 150 | C18: =COUNTIF('Revenus B2B'!A:A,'Revenus par client'!A18) -> 1 | D18: =B18/$B$21 -> 0.00053183444
A21: TOTAL | B21: =SUM(B2:B18) -> 282042.66 | C21: =SUM(C2:C18) -> 58

Sheet Feuille4
A1: Client | B1: Facture | C1: Date | D1: Montant
A2: SAMFI | C2: 45691 | D2: 416

Sheet Feuille5
A1: Client | B1: Facture | C1: Date | D1: Montant
A2: SAMFI | C2: 45691 | D2: 416

Sheet Bilan
A3: Somme de Montant | B3: Étiquettes de colonnes
B4: 45149 | C4: Total 11/08/2023 | D4: 45279 | E4: Total 19/12/2023 | F4: 45282 | G4: Total 22/12/2023 | H4: 45286 | I4: Total 26/12/2023 | J4: 45288 | K4: Total 28/12/2023 | L4: 45316 | M4: Total 25/01/2024 | N4: 45322 | O4: Total 31/01/2024 | P4: 45358 | Q4: Total 07/03/2024 | R4: 45359 | S4: Total 08/03/2024 | T4: 45427 | U4: Total 15/05/2024 | V4: 45455 | W4: Total 12/06/2024 | X4: 45474 | Y4: Total 01/07/2024 | Z4: 45503 | AA4: Total 30/07/2024 | AB4: 45541 | AC4: Total 06/09/2024 | AD4: 45609 | AE4: Total 13/11/2024 | AF4: 45636 | AG4: Total 10/12/2024 | AH4: 45659 | AI4: Total 02/01/2025 | AJ4: 45660 | AK4: Total 03/01/2025 | AL4: 45663 | AM4: Total 06/01/2025 | AN4: 45673 | AO4: Total 16/01/2025 | AP4: 45691 | AQ4: Total 03/02/2025 | AR4: 45698 | AS4: Total 10/02/2025 | AT4: 45718 | AU4: Total 02/03/2025 | AV4: 45721 | AW4: Total 05/03/2025 | AX4: 45722 | AY4: Total 06/03/2025 | AZ4: 45743 | BA4: Total 27/03/2025 | BB4: 45750 | BC4: Total 03/04/2025 | BD4: 45758 | BE4: Total 11/04/2025 | BF4: 45762 | BG4: Total 15/04/2025 | BH4: 45777 | BI4: Total 30/04/2025 | BJ4: 45805 | BK4: Total 28/05/2025 | BL4: 45806 | BM4: Total 29/05/2025 | BN4: 45839 | BO4: Total 01/07/2025 | BP4: 45888 | BQ4: Total 19/08/2025 | BR4: 45911 | BS4: Total 11/09/2025 | BT4: 45944 | BU4: Total 14/10/2025 | BV4: 45947 | BW4: Total 17/10/2025 | BX4: 45978 | BY4: Total 17/11/2025 | BZ4: 45979 | CA4: Total 18/11/2025 | CB4: 45982 | CC4: Total 21/11/2025 | CD4: 45987 | CE4: Total 26/11/2025 | CF4: 46001 | CG4: Total 10/12/2025 | CH4: 46003 | CI4: Total 12/12/2025 | CJ4: 46006 | CK4: Total 15/12/2025 | CL4: 46007 | CM4: Total 16/12/2025 | CN4: Total général
A5: Étiquettes de lignes | B5: 2023 | D5: 2023 | F5: 2023 | H5: 2023 | J5: 2023 | L5: 2024 | N5: 2024 | P5: 2024 | R5: 2024 | T5: 2024 | V5: 2024 | X5: 2024 | Z5: 2024 | AB5: 2024 | AD5: 2024 | AF5: 2024 | AH5: 2025 | AJ5: 2025 | AL5: 2025 | AN5: 2025 | AP5: 2025 | AR5: 2025 | AT5: 2025 | AV5: 2025 | AX5: 2025 | AZ5: 2025 | BB5: 2025 | BD5: 2025 | BF5: 2025 | BH5: 2025 | BJ5: 2025 | BL5: 2025 | BN5: 2025 | BP5: 2025 | BR5: 2025 | BT5: 2025 | BV5: 2025 | BX5: 2025 | BZ5: 2025 | CB5: 2025 | CD5: 2025 | CF5: 2025 | CH5: 2025 | CJ5: 2025 | CL5: 2025
A6: Attijari Bank | R6: 51480 | S6: 51480 | AR6: 17407.5 | AS6: 17407.5 | AV6: 11605 | AW6: 11605 | AZ6: 29012 | BA6: 29012 | CN6: 109504.5
A7: FAC24-02 | R7: 51480 | S7: 51480 | CN7: 51480
A8: Fac25-07 | AR8: 17407.5 | AS8: 17407.5 | CN8: 17407.5
A9: Fac25-10 | AV9: 11605 | AW9: 11605 | CN9: 11605
A10: Fac25-12 | AZ10: 29012 | BA10: 29012 | CN10: 29012
A11: Attijari Leasing | P11: 1830.4 | Q11: 1830.4 | AX11: 2194.5 | AY11: 2194.5 | CN11: 4024.9
A12: FAC24-010 | P12: 1830.4 | Q12: 1830.4 | CN12: 1830.4
A13: Fac25-11 | AX13: 2194.5 | AY13: 2194.5 | CN13: 2194.5
A14: Bank ABC Tunis | CD14: 3737.5 | CE14: 3737.5 | CJ14: 4037.5 | CK14: 4037.5 | CN14: 7775
A15: FAC25-32 | CD15: 3737.5 | CE15: 3737.5 | CN15: 3737.5
A16: FAC25-36 | CJ16: 300 | CK16: 300 | CN16: 300
A17: FAC25-37 | CJ17: 3737.5 | CK17: 3737.5 | CN17: 3737.5
A18: BH BANK | F18: 7470 | G18: 7470 | CN18: 7470
A19: 2023-053 | F19: 7470 | G19: 7470 | CN19: 7470
A20: Digital Services Value | BD20: 224.34 | BE20: 224.34 | CN20: 224.34
A21: FAC25-13BIS | BD21: 224.34 | BE21: 224.34 | CN21: 224.34
A22: Everience | AJ22: 50000 | AK22: 50000 | CN22: 50000
A23: FAC25-02 | AJ23: 50000 | AK23: 50000 | CN23: 50000
A24: Lilas | BZ24: 1785 | CA24: 1785 | CN24: 1785
A25: FAC25-29 | BZ25: 1785 | CA25: 1785 | CN25: 1785
A26: N N FOOD | CL26: 1720 | CM26: 1720 | CN26: 1720
A27: FAC25-38 | CL27: 1720 | CM27: 1720 | CN27: 1720
A28: SAMFI | J28: 800 | K28: 800 | N28: 751 | O28: 751 | X28: 544 | Y28: 544 | Z28: 744 | AA28: 744 | AB28: 544 | AC28: 544 | AH28: 352 | AI28: 352 | AP28: 416 | AQ28: 416 | AT28: 527 | AU28: 527 | BB28: 352 | BC28: 352 | BH28: 576 | BI28: 576 | BJ28: 727 | BK28: 727 | BL28: 276 | BM28: 276 | BN28: 384 | BO28: 384 | BP28: 320 | BQ28: 320 | BR28: 484 | BS28: 484 | BT28: 224 | BU28: 224 | CB28: 352 | CC28: 352 | CN28: 8373
A29: 2023-062 | J29: 800 | K29: 800 | CN29: 800
A30: 2024-003 | N30: 751 | O30: 751 | CN30: 751
A31: FAC24-013 | BJ31: 727 | BK31: 727 | CN31: 727
A32: FAC24-016 | X32: 544 | Y32: 544 | CN32: 544
A33: FAC24-017 | Z33: 744 | AA33: 744 | CN33: 744
A34: FAC24-018 | AB34: 544 | AC34: 544 | CN34: 544
A35: (vide) | AH35: 352 | AI35: 352 | AP35: 416 | AQ35: 416 | AT35: 527 | AU35: 527 | BB35: 352 | BC35: 352 | BH35: 576 | BI35: 576 | BL35: 276 | BM35: 276 | BN35: 384 | BO35: 384 | BP35: 320 | BQ35: 320 | BR35: 484 | BS35: 484 | BT35: 224 | BU35: 224 | CB35: 352 | CC35: 352 | CN35: 4263
A36: SBCD | CH36: 605 | CI36: 605 | CN36: 605
A37: FAC25-34 | CH37: 605 | CI37: 605 | CN37: 605
A38: SOFIA TECH | H38: 5460 | I38: 5460 | CN38: 5460
A39: 2023-057 | H39: 5460 | I39: 5460 | CN39: 5460
A40: SOTIC | AL40: 160 | AM40: 160 | AP40: 160 | AQ40: 160 | AT40: 224 | AU40: 224 | BB40: 256 | BC40: 256 | BH40: 303 | BI40: 303 | BL40: 224 | BM40: 224 | BN40: 192 | BO40: 192 | BP40: 32 | BQ40: 32 | BR40: 128 | BS40: 128 | BT40: 96 | BU40: 96 | CB40: 96 | CC40: 96 | CN40: 1871
A41: (vide) | AL41: 160 | AM41: 160 | AP41: 160 | AQ41: 160 | AT41: 224 | AU41: 224 | BB41: 256 | BC41: 256 | BH41: 303 | BI41: 303 | BL41: 224 | BM41: 224 | BN41: 192 | BO41: 192 | BP41: 32 | BQ41: 32 | BR41: 128 | BS41: 128 | BT41: 96 | BU41: 96 | CB41: 96 | CC41: 96 | CN41: 1871
A42: Stram | D42: 5100 | E42: 5100 | CN42: 5100
...
