Workbook

Sheet Dashboard
A3: Total Ventes (DT) | B3: =SUM(Sheet1!F2:F1000) -> 26859
A4: Total Remises (DT) | B4: =SUM(Sheet1!G2:G1000) -> 2321
A5: Nombre de Tickets | B5: =COUNTA(Sheet1!B2:B1000) -> 516
A8: Répartition par Type de Paiement | D8: Total par Jour
A9: Type | B9: Total (DT) | D9: Date | E9: Total (DT)
A10: Espèces | B10: =SUMIF(Sheet1!H2:H1000,"Espèces",Sheet1!F2:F1000) -> 15726
A11: Carte | B11: =SUMIF(Sheet1!H2:H1000,"Carte",Sheet1!F2:F1000) -> 11133 | D11: 45882 | E11: =SUMIF(Sheet1!$A$2:$A$1000,D11,Sheet1!$F$2:$F$1000) -> 975
D12: 45883 | E12: =SUMIF(Sheet1!$A$2:$A$1000,D12,Sheet1!$F$2:$F$1000) -> 864
D13: 45884 | E13: =SUMIF(Sheet1!$A$2:$A$1000,D13,Sheet1!$F$2:$F$1000) -> 565
D14: 45885 | E14: =SUMIF(Sheet1!$A$2:$A$1000,D14,Sheet1!$F$2:$F$1000) -> 1910
D15: 45886 | E15: =SUMIF(Sheet1!$A$2:$A$1000,D15,Sheet1!$F$2:$F$1000) -> 275
D16: 45887 | E16: =SUMIF(Sheet1!$A$2:$A$1000,D16,Sheet1!$F$2:$F$1000) -> 565
D17: 45888 | E17: =SUMIF(Sheet1!$A$2:$A$1000,D17,Sheet1!$F$2:$F$1000) -> 505
D18: 45889 | E18: =SUMIF(Sheet1!$A$2:$A$1000,D18,Sheet1!$F$2:$F$1000) -> 535
D19: 45890 | E19: =SUMIF(Sheet1!$A$2:$A$1000,D19,Sheet1!$F$2:$F$1000) -> 805
D20: 45891 | E20: =SUMIF(Sheet1!$A$2:$A$1000,D20,Sheet1!$F$2:$F$1000) -> 435
D21: 45892 | E21: =SUMIF(Sheet1!$A$2:$A$1000,D21,Sheet1!$F$2:$F$1000) -> 290
D22: 45893 | E22: =SUMIF(Sheet1!$A$2:$A$1000,D22,Sheet1!$F$2:$F$1000) -> 563
D23: 45894 | E23: =SUMIF(Sheet1!$A$2:$A$1000,D23,Sheet1!$F$2:$F$1000) -> 390
... D62: 45933 | E62: =SUMIF(Sheet1!$A$2:$A$1000,D62,Sheet1!$F$2:$F$1000) -> 827

Sheet Sheet1
A1: Date | B1: Produit | C1: Quantité | D1: Prix Unitaire (DT) | E1: Remise (%) | F1: Montant Total (DT) | G1: Montant Remise (DT) | H1: Type de Paiement (Espèces / Carte) | I1: Client (optionnel) | J1: Remarques
A2: 45911 | B2: Plateau 30*10 | C2: 1 | D2: 70 | F2: =C2*D2*(1-E2/100) -> 70 | G2: =C2*D2*(E2/100) -> 0 | H2: Espèces
A3: 45911 | B3: Plateau 30*10 | C3: 1 | D3: 70 | F3: =C3*D3*(1-E3/100) -> 70 | G3: =C3*D3*(E3/100) -> 0 | H3: carte
A4: 45911 | B4: Plateau 20*10 | C4: 1 | D4: 55 | F4: =C4*D4*(1-E4/100) -> 55 | G4: =C4*D4*(E4/100) -> 0 | H4: carte
A5: 45911 | B5: Plateau 20*20 | C5: 1 | D5: 70 | F5: =C5*D5*(1-E5/100) -> 70 | G5: =C5*D5*(E5/100) -> 0 | H5: Espèces
A6: 45911 | B6: Magnet fridge | C6: 1 | D6: 10 | F6: =C6*D6*(1-E6/100) -> 10 | G6: =C6*D6*(E6/100) -> 0 | H6: Espèces
A7: 45911 | B7: Porte clé chachia | C7: 1 | D7: 10 | F7: =C7*D7*(1-E7/100) -> 10 | G7: =C7*D7*(E7/100) -> 0 | H7: Espèces
A8: 45911 | B8: Couffin sac à main | C8: 1 | D8: 110 | E8: =10/110*100 -> 9.0909091 | F8: =C8*D8*(1-E8/100) -> 100 | G8: 10 | H8: Espèces
A9: 45911 | B9: Plateau 20*10 | C9: 1 | D9: 55 | F9: =C9*D9*(1-E9/100) -> 55 | G9: =C9*D9*(E9/100) -> 0 | H9: Espèces
A10: 45911 | B10: Planche Bois | C10: 1 | D10: 35 | F10: =C10*D10*(1-E10/100) -> 35 | G10: =C10*D10*(E10/100) -> 0 | H10: Espèces
A11: 45911 | B11: Fouta | C11: 1 | D11: 25 | E11: 20 | F11: =C11*D11*(1-E11/100) -> 20 | G11: =C11*D11*(E11/100) -> 5 | H11: Espèces
A12: 45912 | B12: Couffin sac à main | C12: 1 | D12: 110 | F12: =C12*D12*(1-E12/100) -> 110 | G12: =C12*D12*(E12/100) -> 0 | H12: carte
A13: 45912 | B13: fridge magnet | C13: 1 | D13: 10 | F13: =C13*D13*(1-E13/100) -> 10 | G13: =C13*D13*(E13/100) -> 0 | H13: carte
A14: 45913 | B14: mouton T3 | C14: 1 | D14: 80 | F14: =C14*D14*(1-E14/100) -> 80 | G14: =C14*D14*(E14/100) -> 0 | H14: carte
A15: 45913 | B15: Planche Bois | C15: 3 | D15: 40 | F15: =C15*D15*(1-E15/100) -> 120 | G15: =C15*D15*(E15/100) -> 0 | H15: carte
A16: 45913 | B16: Sous plat bois | C16: 1 | D16: 40 | F16: =C16*D16*(1-E16/100) -> 40 | G16: =C16*D16*(E16/100) -> 0 | H16: carte
A17: 45913 | B17: Bouteille huile | C17: 2 | D17: 30 | F17: =C17*D17*(1-E17/100) -> 60 | G17: =C17*D17*(E17/100) -> 0 | H17: carte
A18: 45913 | B18: bouteille huile | C18: 1 | D18: 30 | E18: =10/30*100 -> 33.333333 | F18: =C18*D18*(1-E18/100) -> 20 | G18: 10 | H18: Espèces
A19: 45913 | B19: fridge magnet | C19: 1 | D19: 10 | F19: =C19*D19*(1-E19/100) -> 10 | G19: =C19*D19*(E19/100) -> 0 | H19: Espèces
A20: 45913 | B20: bougie sidi bousaid MF | C20: 2 | D20: 50 | F20: =C20*D20*(1-E20/100) -> 100 | G20: =C20*D20*(E20/100) -> 0 | H20: carte
A21: 45913 | B21: bougie trio | C21: 1 | D21: 20 | F21: =C21*D21*(1-E21/100) -> 20 | G21: =C21*D21*(E21/100) -> 0 | H21: carte
A22: 45913 | B22: fridge magnet | C22: 2 | D22: 10 | F22: =C22*D22*(1-E22/100) -> 20 | G22: =C22*D22*(E22/100) -> 0 | H22: carte
A23: 45913 | B23: mouton T3 | C23: 1 | D23: 70 | F23: =C23*D23*(1-E23/100) -> 70 | G23: 0 | H23: Espèces
A24: 45914 | B24: tasse + st coeur irr | C24: 1 | D24: 30 | F24: =C24*D24*(1-E24/100) -> 30 | G24: =C24*D24*(E24/100) -> 0 | H24: Espèces
A25: 45914 | B25: bougie sidi bousaid GF | C25: 1 | D25: 60 | E25: =5/60*100 -> 8.3333333 | F25: =C25*D25*(1-E25/100) -> 55 | G25: =C25*D25*(E25/100) -> 5 | H25: Espèces
A26: 45914 | B26: bouteille huile d'olive poisson pf | C26: 1 | D26: 25 | E26: 20 | F26: =C26*D26*(1-E26/100) -> 20 | G26: =C26*D26*(E26/100) -> 5 | H26: carte
A27: 45914 | B27: Plateau 20*20 | C27: 1 | D27: 70 | F27: =C27*D27*(1-E27/100) -> 70 | G27: =C27*D27*(E27/100) -> 0 | H27: Espèces
A28: 45914 | B28: Bouteille huile d'olive pf | C28: 1 | D28: 25 | F28: =C28*D28*(1-E28/100) -> 25 | G28: =C28*D28*(E28/100) -> 0 | H28: Espèces
A29: 45914 | B29: Tote Bag | C29: 1 | D29: 20 | E29: 25 | F29: =C29*D29*(1-E29/100) -> 15 | G29: =C29*D29*(E29/100) -> 5 | H29: Espèces
A30: 45914 | B30: Magnet fridge | C30: 2 | D30: 10 | F30: =C30*D30*(1-E30/100) -> 20 | G30: =C30*D30*(E30/100) -> 0 | H30: Espèces
A31: 45914 | B31: Fouta | C31: 1 | D31: 20 | F31: =C31*D31*(1-E31/100) -> 20 | G31: =C31*D31*(E31/100) -> 0 | H31: carte
A32: 45914 | B32: Porte clé porte | C32: 2 | D32: 10 | F32: =C32*D32*(1-E32/100) -> 20 | G32: =C32*D32*(E32/100) -> 0 | H32: carte
A33: 45914 | B33: Plateau 30*20 | C33: 1 | D33: 100 | F33: =C33*D33*(1-E33/100) -> 100 | G33: =C33*D33*(E33/100) -> 0 | H33: carte
A34: 45914 | B34: vase Poissons | C34: 1 | D34: 25 | F34: =C34*D34*(1-E34/100) -> 25 | G34: =C34*D34*(E34/100) -> 0 | H34: carte
A35: 45914 | B35: Plateau 30*10 | C35: 1 | D35: 70 | F35: =C35*D35*(1-E35/100) -> 70 | G35: =C35*D35*(E35/100) -> 0 | H35: carte
A36: 45914 | B36: BROC verre GM | C36: 1 | D36: 55 | E36: =5/55*100 -> 9.0909091 | F36: =C36*D36*(1-E36/100) -> 50 | G36: =C36*D36*(E36/100) -> 5 | H36: Espèces
A37: 45915 | B37: Mouton PF | C37: 1 | D37: 50 | F37: =C37*D37*(1-E37/100) -> 50 | G37: =C37*D37*(E37/100) -> 0 | H37: carte
A38: 45915 | B38: Poisson avec Tige | C38: 1 | D38: 90 | F38: =C38*D38*(1-E38/100) -> 90 | G38: =C38*D38*(E38/100) -> 0 | H38: carte
A39: 45915 | B39: Mouton PF | C39: 1 | D39: 50 | F39: =C39*D39*(1-E39/100) -> 50 | G39: =C39*D39*(E39/100) -> 0 | H39: Espèces
A40: 45915 | B40: Porte clé chachia | C40: 1 | D40: 10 | F40: =C40*D40*(1-E40/100) -> 10 | G40: =C40*D40*(E40/100) -> 0 | H40: Espèces
...
